ERROR 2017-05-02 15:07:05,108 exception 8478 139902158927616 Internal Server Error: /disburseDocsData/152132
Traceback (most recent call last):
  File "/home/analyzer/virtual_environment/shg/local/lib/python2.7/site-packages/django/core/handlers/exception.py", line 39, in inner
    response = get_response(request)
  File "/home/analyzer/virtual_environment/shg/local/lib/python2.7/site-packages/django/core/handlers/base.py", line 187, in _get_response
    response = self.process_exception_by_middleware(e, request)
  File "/home/analyzer/virtual_environment/shg/local/lib/python2.7/site-packages/django/core/handlers/base.py", line 185, in _get_response
    response = wrapped_callback(request, *callback_args, **callback_kwargs)
  File "/home/analyzer/shg_staging_test/shg_bpm_portal/shgapp/views/decorator.py", line 22, in checkLastLogin
    return func(request, *args, **kwargs)
  File "/home/analyzer/shg_staging_test/shg_bpm_portal/shgapp/views/kyc.py", line 453, in disburseDocsData
    errorLog.error("Exception raised inside disburseDocsData(request, loanId):" + e)
TypeError: cannot concatenate 'str' and 'ShgInvalidRequest' objects
